Workbook

Sheet Instrucciones
A1: Plataforma de Seguimiento Toyota Corregidora — versión Excel
A3: Cómo usar este archivo:
A4: 1. Ve a la pestaña 'Clientes' y da de alta cada cliente en una fila nueva (usa los menús desplegables en Vehículo, Método de Compra, Tipo de Persona, Avalúo, Primera Visita y Etapa).
A5: 2. La fila cambia de color automáticamente según la Etapa que selecciones (Prospecto, Apartado, Toma de vehículo, Pago, Contrato, Facturación, Programación, Entregado).
A6: 3. Las columnas Q a Z generan el texto del mensaje y un enlace 'Enviar' que abre WhatsApp Web con el mensaje ya redactado — solo da clic y presiona enviar.
A7: 4. En 'Requisitos' filtra por Método de Compra y Tipo de Persona con el autofiltro para ver la checklist correspondiente; ahí también están los beneficios de crédito.
A8: 5. En 'Fichas y Beneficios' tienes el nombre del PDF de cada vehículo (guárdalos en una carpeta llamada 'fichas' junto a este archivo).
A9: 6. En 'Facturación' selecciona el nombre del cliente (ya dado de alta en Clientes) y llena sus datos; el mensaje de confirmación y el enlace de WhatsApp se generan solos.
A11: Nota: los enlaces de WhatsApp requieren que el número de teléfono tenga 10 dígitos (se le agrega automáticamente el 52 de México).
A12: Nota: al abrir el archivo, Excel puede preguntar si deseas habilitar el cálculo de fórmulas o el contenido externo — acepta para que los mensajes se generen correctamente.

Sheet Config
A1: Firma (footer de mensajes) | B1: ="Atentamente."&CHAR(10)&CHAR(10)&"*Alejandro Estrada*"&CHAR(10)&"Asesor de ventas"&CHAR(10)&"Toyota Corregidora"&CHAR(10)&"4427485194"&CHAR(10)&"jestrada@toyotacorregidora.mx" | D1: Vehículos | E1: Método de Compra | F1: Tipo de Persona | G1: Sí/No | H1: Etapa | I1: Tipo de Mensaje
D2: Yaris Sedan | E2: Crédito | F2: Persona física | G2: Sí | H2: Prospecto / Visita | I2: Bienvenida (primera visita)
D3: Yaris Sedan HEV | E3: Contado | F3: Persona física con actividad empresarial | G3: No | H3: Apartado | I3: Seguimiento
D4: Yaris HB | F4: Persona moral | H4: Toma de vehículo | I4: Aviso de Etapa
D5: GR Yaris | H5: Pago vehículo a cuenta | I5: Requisitos
D6: Corolla | H6: Firma de contrato | I6: Datos de Facturación
D7: GR Corolla | H7: Facturación | I7: Cumpleaños
D8: Camry | H8: Programación de entrega | I8: Aniversario
D9: Prius | H9: Entregado
D10: Supra
D11: Raize
D12: Avanza
D13: Corolla Cross
D14: Rav-4
D15: Highlander
D16: Sienna
D17: 4Runner
D18: Sequoia
D19: Hilux
D20: Tacoma
D21: Tundra
... D23: Otro (especificar)

Sheet Clientes
A1: No. | B1: Nombre | C1: Teléfono | D1: Vehículo | E1: Versión | F1: Método de Compra | G1: Tipo de Persona | H1: Avalúo (Sí/No) | I1: Vehículo Avalúo | J1: Oferta Avalúo | K1: Comentarios | L1: Primera Visita (Sí/No) | M1: Etapa | N1: Fecha Registro | O1: Cumpleaños | P1: Fecha Entrega (Aniversario) | Q1: Mensaje Bienvenida | R1: WhatsApp Bienvenida | S1: Mensaje Seguimiento | T1: WhatsApp Seguimiento | U1: Mensaje por Etapa | V1: WhatsApp Etapa | W1: Mensaje Cumpleaños | X1: WhatsApp Cumpleaños | Y1: Mensaje Aniversario | Z1: WhatsApp Aniversario | AA1: Tipo de Mensaje a Enviar | AB1: Enviar Mensaje Seleccionado | AC1: Mensaje Requisitos (auto) | AD1: Mensaje Facturación (auto, si ya está en la pestaña Facturación)
A2: =IF(B2="","",ROW()-1) | B2: Fernando Velasco | C2: 4424479460 | D2: Corolla Cross | E2: XLE | F2: Contado | G2: Persona física | H2: No | K2: Sale de viaje a Europa y regresa en noviembre o diciembre | L2: Sí | M2: Prospecto / Visita | N2: 46253 | Q2: =IF(OR(B2="",L2<>"Sí"),"","Hola, "&B2&", excelente día. Le saluda *Alejandro Estrada* de Toyota Corregidora."&CHAR(10)&"Muchas gracias por visitarnos y conocer la *"&D2&"*. Fue un placer atenderle. Me pongo a sus órdenes por este medio para resolver cualquier duda que haya surgido o para agendarle una prueba de manejo."&CHAR(10)&"Quedo muy pendiente de lo que necesite para ayudarle a estrenar su próximo Toyota. ¡Saludos!"&CHAR(10)&CHAR(10)&Config!$B$1) | R2: =IF(Q2="","",HYPERLINK("https://wa.me/52"&C2&"?text="&_xlfn.ENCODEURL(Q2),"Enviar Bienvenida")) | S2: =IF(B2="","","Hola, "&B2&", muy buen día."&CHAR(10)&"Espero que esté teniendo una excelente semana. Le escribo para saber si tiene alguna duda sobre la oferta del *"&D2&"* que revisamos, con gusto le apoyo con información técnica o con las opciones de financiamiento disponibles."&CHAR(10)&"Quedo atento a sus comentarios para seguir avanzando hacia la entrega de su próximo Toyota. Gracias por su tiempo y confianza."&CHAR(10)&CHAR(10)&Config!$B$1) | T2: =IF(S2="","",HYPERLINK("https://wa.me/52"&C2&"?text="&_xlfn.ENCODEURL(S2),"Enviar Seguimiento")) | U2: =IF(B2="","",_xlfn.SWITCH(M2,"Apartado","Hola, "&B2&", buen día. Le confirmo que su apartado por el *"&D2&"* quedó registrado correctamente. Seguimos con el proceso y le mantendré informado(a) de cada paso.","Toma de vehículo","Hola, "&B2&", le comparto que estamos en el proceso de toma de su vehículo actual. En cuanto tengamos el resultado le aviso para continuar con el siguiente paso.","Pago vehículo a cuenta","Hola, "&B2&", quedamos en proceso de pago del vehículo que se toma a cuenta. Cualquier documento o aclaración que se requiera se lo haré saber por este medio.","Firma de contrato","Hola, "&B2&", ya estamos listos para agendar la firma de su contrato. ¿Qué día y hora se le facilita para realizarla?","Facturación","Hola, "&B2&", su unidad ya está en proceso de facturación. En breve le comparto los datos para su confirmación.","Programación de entrega","Hola, "&B2&", con gusto le comparto que ya podemos programar la entrega de su *"&D2&"*. ¿Qué día y hora le acomodan mejor?","Entregado","Hola, "&B2&", ¡muchas felicidades por estrenar su *"&D2&"*! Fue un gusto acompañarle en este proceso. Quedo pendiente de cualquier duda y con gusto le agendo su próxima cita de servicio cuando lo necesite.","Hola, "&B2&", seguimos en contacto para avanzar con el proceso de su próximo Toyota.")&CHAR(10)&CHAR(10)&Config!$B$1) | V2: =IF(U2="","",HYPERLINK("https://wa.me/52"&C2&"?text="&_xlfn.ENCODEURL(U2),"Enviar aviso de etapa")) | W2: =IF(OR(B2="",O2=""),"","Hola, "&B2&", ¡feliz cumpleaños! Le deseo un excelente día rodeado de quienes más quiere. Ha sido un placer acompañarle desde que estrenó su Toyota. ¡Un abrazo!"&CHAR(10)&CHAR(10)&Config!$B$1) | X2: =IF(W2="","",HYPERLINK("https://wa.me/52"&C2&"?text="&_xlfn.ENCODEURL(W2),"Enviar felicitación")) | Y2: =IF(OR(B2="",P2=""),"","Hola, "&B2&", hoy se cumple un año más desde que estrenó su *"&D2&"*. Espero que haya sido un gran compañero de camino. Cualquier cosa que necesite, aquí estoy para apoyarle."&CHAR(10)&CHAR(10)&Config!$B$1) | Z2: =IF(Y2="","",HYPERLINK("https://wa.me/52"&C2&"?text="&_xlfn.ENCODEURL(Y2),"Enviar aniversario")) | AB2: =IF(OR(B2="",AA2=""),"",HYPERLINK("https://wa.me/52"&C2&"?text="&_xlfn.ENCODEURL(_xlfn.SWITCH(AA2,"Bienvenida (primera visita)",Q2,"Seguimiento",S2,"Aviso de Etapa",U2,"Requisitos",AC2,"Datos de Facturación",AD2,"Cumpleaños",W2,"Aniversario",Y2,"")),"Enviar mensaje seleccionado")) | AC2: =IF(B2="","",_xlfn.SWITCH(F2&"|"&G2,"Crédito|Persona física","Hola, "&B2&", para continuar con el proceso de tu *"&D2&"* por "&F2&", estos son los documentos que necesitamos:"&CHAR(10)&CHAR(10)&"- INE"&CHAR(10)&"- Comprobante de domicilio (luz), a nombre del titular"&CHAR(10)&"- Estados de cuenta de los últimos 3 meses"&CHAR(10)&"- Constancia de situación fiscal (no mayor a 3 meses)","Crédito|Persona física con actividad empresarial","Hola, "&B2&", para continuar con el proceso de tu *"&D2&"* por "&F2&", estos son los documentos que necesitamos:"&CHAR(10)&CHAR(10)&"- INE"&CHAR(10)&"- Comprobante de domicilio (luz), a nombre del titular"&CHAR(10)&"- Estados de cuenta de los últimos 3 meses"&CHAR(10)&"- Constancia de situación fiscal (no mayor a 3 meses)"&CHAR(10)&"- Última declaración anual con acuse de recibo","Crédito|Persona moral","Hola, "&B2&", para continuar con el proceso de tu *"&D2&"* por "&F2&", estos son los documentos que necesitamos:"&CHAR(10)&CHAR(10)&"- Identificación oficial vigente del representante legal (INE o pasaporte)"&CHAR(10)&"- Comprobante de domicilio fiscal de la empresa (CFE, no mayor a 3 meses)"&CHAR(10)&"- Comprobante de domicilio del representante legal (CFE, no mayor a 3 meses)"&CHAR(10)&"- Últimos 3 meses de estados de cuenta bancarios de la empresa"&CHAR(10)&"- Constancia de situación fiscal de la empresa (no mayor a 3 meses)"&CHAR(10)&"- Constancia de situación fiscal del representante legal (no mayor a 3 meses)"&CHAR(10)&"- Declaración anual del último ejercicio, en digital, con acuse de recibo"&CHAR(10)&"- Estados financieros de la empresa (Resultados y Balance General), no mayor a 3 meses"&CHAR(10)&"- Escritura constitutiva, poderes o reformas de estatutos (primer acta, poder del representante y última acta)","Contado|Persona física","Hola, "&B2&", para continuar con el proceso de tu *"&D2&"* por "&F2&", estos son los documentos que necesitamos:"&CHAR(10)&CHAR(10)&"- INE"&CHAR(10)&"- Comprobante de domicilio"&CHAR(10)&"- Constancia de situación fiscal (no mayor a 3 meses)","Contado|Persona física con actividad empresarial","Hola, "&B2&", para continuar con el proceso de tu *"&D2&"* por "&F2&", estos son los documentos que necesitamos:"&CHAR(10)&CHAR(10)&"- INE"&CHAR(10)&"- Comprobante de domicilio"&CHAR(10)&"- Constancia de situación fiscal (no mayor a 3 meses)","Contado|Persona moral","Hola, "&B2&", para continuar con el proceso de tu *"&D2&"* por "&F2&", estos son los documentos que necesitamos:"&CHAR(10)&CHAR(10)&"- Identificación oficial vigente del representante legal y accionistas"&CHAR(10)&"- Comprobante de domicilio fiscal de la empresa (no mayor a 3 meses)"&CHAR(10)&"- Comprobante de domicilio del representante legal y accionistas (no mayor a 3 meses)"&CHAR(10)&"- Constancia de situación fiscal de la empresa (no mayor a 3 meses)"&CHAR(10)&"- Constancia de situación fiscal del representante legal y accionistas (no mayor a 3 meses)"&CHAR(10)&"- Escritura constitutiva, poderes o reformas de estatutos (primer acta, poder del representante y última acta)","Selecciona Método de Compra y Tipo de Persona.")&CHAR(10)&CHAR(10)&Config!$B$1) | AD2: =IFERROR(INDEX(Facturación!$Q:$Q,MATCH(B2,Facturación!$A:$A,0)),"")
A3: =IF(B3="","",ROW()-1) | B3: Adalberto Rusiles | C3: 4422055531 | D3: Hilux | E3: Base | F3: Crédito | G3: Persona física | H3: No | K3: En busca de la pickup mas pequeña | L3: Sí | M3: Prospecto / Visita | N3: 46251 | Q3: =IF(OR(B3="",L3<>"Sí"),"","Hola, "&B3&", excelente día. Le saluda *Alejandro Estrada* de Toyota Corregidora."&CHAR(10)&"Muchas gracias por visitarnos y conocer la *"&D3&"*. Fue un placer atenderle. Me pongo a sus órdenes por este medio para resolver cualquier duda que haya surgido o para agendarle una prueba de manejo."&CHAR(10)&"Quedo muy pendiente de lo que necesite para ayudarle a estrenar su próximo Toyota. ¡Saludos!"&CHAR(10)&CHAR(10)&Config!$B$1) | R3: =IF(Q3="","",HYPERLINK("https://wa.me/52"&C3&"?text="&_xlfn.ENCODEURL(Q3),"Enviar Bienvenida")) | S3: =IF(B3="","","Hola, "&B3&", muy buen día."&CHAR(10)&"Espero que esté teniendo una excelente semana. Le escribo para saber si tiene alguna duda sobre la oferta del *"&D3&"* que revisamos, con gusto le apoyo con información técnica o con las opciones de financiamiento disponibles."&CHAR(10)&"Quedo atento a sus comentarios para seguir avanzando hacia la entrega de su próximo Toyota. Gracias por su tiempo y confianza."&CHAR(10)&CHAR(10)&Config!$B$1) | T3: =IF(S3="","",HYPERLINK("https://wa.me/52"&C3&"?text="&_xlfn.ENCODEURL(S3),"Enviar Seguimiento")) | U3: =IF(B3="","",_xlfn.SWITCH(M3,"Apartado","Hola, "&B3&", buen día. Le confirmo que su apartado por el *"&D3&"* quedó registrado correctamente. Seguimos con el proceso y le mantendré informado(a) de cada paso.","Toma de vehículo","Hola, "&B3&", le comparto que estamos en el proceso de toma de su vehículo actual. En cuanto tengamos el resultado le aviso para continuar con el siguiente paso.","Pago vehículo a cuenta","Hola, "&B3&", quedamos en proceso de pago del vehículo que se toma a cuenta. Cualquier documento o aclaración que se requiera se lo haré saber por este medio.","Firma de contrato","Hola, "&B3&", ya estamos listos para agendar la firma de su contrato. ¿Qué día y hora se le facilita para realizarla?","Facturación","Hola, "&B3&", su unidad ya está en proceso de facturación. En breve le comparto los datos para su confirmación.","Programación de entrega","Hola, "&B3&", con gusto le comparto que ya podemos programar la entrega de su *"&D3&"*. ¿Qué día y hora le acomodan mejor?","Entregado","Hola, "&B3&", ¡muchas felicidades por estrenar su *"&D3&"*! Fue un gusto acompañarle en este proceso. Quedo pendiente de cualquier duda y con gusto le agendo su próxima cita de servicio cuando lo necesite.","Hola, "&B3&", seguimos en contacto para avanzar con el proceso de su próximo Toyota.")&CHAR(10)&CHAR(10)&Config!$B$1) | V3: =IF(U3="","",HYPERLINK("https://wa.me/52"&C3&"?text="&_xlfn.ENCODEURL(U3),"Enviar aviso de etapa")) | W3: =IF(OR(B3="",O3=""),"","Hola, "&B3&", ¡feliz cumpleaños! Le deseo un excelente día rodeado de quienes más quiere. Ha sido un placer acompañarle desde que estrenó su Toyota. ¡Un abrazo!"&CHAR(10)&CHAR(10)&Config!$B$1) | X3: =IF(W3="","",HYPERLINK("https://wa.me/52"&C3&"?text="&_xlfn.ENCODEURL(W3),"Enviar felicitación")) | Y3: =IF(OR(B3="",P3=""),"","Hola, "&B3&", hoy se cumple un año más desde que estrenó su *"&D3&"*. Espero que haya sido un gran compañero de camino. Cualquier cosa que necesite, aquí estoy para apoyarle."&CHAR(10)&CHAR(10)&Config!$B$1) | Z3: =IF(Y3="","",HYPERLINK("https://wa.me/52"&C3&"?text="&_xlfn.ENCODEURL(Y3),"Enviar aniversario")) | AB3: =IF(OR(B3="",AA3=""),"",HYPERLINK("https://wa.me/52"&C3&"?text="&_xlfn.ENCODEURL(_xlfn.SWITCH(AA3,"Bienvenida (primera visita)",Q3,"Seguimiento",S3,"Aviso de Etapa",U3,"Requisitos",AC3,"Datos de Facturación",AD3,"Cumpleaños",W3,"Aniversario",Y3,"")),"Enviar mensaje seleccionado")) | AC3: =IF(B3="","",_xlfn.SWITCH(F3&"|"&G3,"Crédito|Persona física","Hola, "&B3&", para continuar con el proceso de tu *"&D3&"* por "&F3&", estos son los documentos que necesitamos:"&CHAR(10)&CHAR(10)&"- INE"&CHAR(10)&"- Comprobante de domicilio (luz), a nombre del titular"&CHAR(10)&"- Estados de cuenta de los últimos 3 meses"&CHAR(10)&"- Constancia de situación fiscal (no mayor a 3 meses)","Crédito|Persona física con actividad empresarial","Hola, "&B3&", para continuar con el proceso de tu *"&D3&"* por "&F3&", estos son los documentos que necesitamos:"&CHAR(10)&CHAR(10)&"- INE"&CHAR(10)&"- Comprobante de domicilio (luz), a nombre del titular"&CHAR(10)&"- Estados de cuenta de los últimos 3 meses"&CHAR(10)&"- Constancia de situación fiscal (no mayor a 3 meses)"&CHAR(10)&"- Última declaración anual con acuse de recibo","Crédito|Persona moral","Hola, "&B3&", para continuar con el proceso de tu *"&D3&"* por "&F3&", estos son los documentos que necesitamos:"&CHAR(10)&CHAR(10)&"- Identificación oficial vigente del representante legal (INE o pasaporte)"&CHAR(10)&"- Comprobante de domicilio fiscal de la empresa (CFE, no mayor a 3 meses)"&CHAR(10)&"- Comprobante de domicilio del representante legal (CFE, no mayor a 3 meses)"&CHAR(10)&"- Últimos 3 meses de estados de cuenta bancarios de la empresa"&CHAR(10)&"- Constancia de situación fiscal de la empresa (no mayor a 3 meses)"&CHAR(10)&"- Constancia de situación fiscal del representante legal (no mayor a 3 meses)"&CHAR(10)&"- Declaración anual del último ejercicio, en digital, con acuse de recibo"&CHAR(10)&"- Estados financieros de la empresa (Resultados y Balance General), no mayor a 3 meses"&CHAR(10)&"- Escritura constitutiva, poderes o reformas de estatutos (primer acta, poder del representante y última acta)","Contado|Persona física","Hola, "&B3&", para continuar con el proceso de tu *"&D3&"* por "&F3&", estos son los documentos que necesitamos:"&CHAR(10)&CHAR(10)&"- INE"&CHAR(10)&"- Comprobante de domicilio"&CHAR(10)&"- Constancia de situación fiscal (no mayor a 3 meses)","Contado|Persona física con actividad empresarial","Hola, "&B3&", para continuar con el proceso de tu *"&D3&"* por "&F3&", estos son los documentos que necesitamos:"&CHAR(10)&CHAR(10)&"- INE"&CHAR(10)&"- Comprobante de domicilio"&CHAR(10)&"- Constancia de situación fiscal (no mayor a 3 meses)","Contado|Persona moral","Hola, "&B3&", para continuar con el proceso de tu *"&D3&"* por "&F3&", estos son los documentos que necesitamos:"&CHAR(10)&CHAR(10)&"- Identificación oficial vigente del representante legal y accionistas"&CHAR(10)&"- Comprobante de domicilio fiscal de la empresa (no mayor a 3 meses)"&CHAR(10)&"- Comprobante de domicilio del representante legal y accionistas (no mayor a 3 meses)"&CHAR(10)&"- Constancia de situación fiscal de la empresa (no mayor a 3 meses)"&CHAR(10)&"- Constancia de situación fiscal del representante legal y accionistas (no mayor a 3 meses)"&CHAR(10)&"- Escritura constitutiva, poderes o reformas de estatutos (primer acta, poder del representante y última acta)","Selecciona Método de Compra y Tipo de Persona.")&CHAR(10)&CHAR(10)&Config!$B$1) | AD3: =IFERROR(INDEX(Facturación!$Q:$Q,MATCH(B3,Facturación!$A:$A,0)),"")
A4: =IF(B4="","",ROW()-1) | B4: Miguel Corona | C4: 4424479460 | D4: Rav-4 | E4: XLE | F4: Contado | G4: Persona física | H4: No | K4: Cambiar a credito 100k | L4: Sí | M4: Apartado | N4: 46251 | O4: 46363 | Q4: =IF(OR(B4="",L4<>"Sí"),"","Hola, "&B4&", excelente día. Le saluda *Alejandro Estrada* de Toyota Corregidora."&CHAR(10)&"Muchas gracias por visitarnos y conocer la *"&D4&"*. Fue un placer atenderle. Me pongo a sus órdenes por este medio para resolver cualquier duda que haya surgido o para agendarle una prueba de manejo."&CHAR(10)&"Quedo muy pendiente de lo que necesite para ayudarle a estrenar su próximo Toyota. ¡Saludos!"&CHAR(10)&CHAR(10)&Config!$B$1) | R4: =IF(Q4="","",HYPERLINK("https://wa.me/52"&C4&"?text="&_xlfn.ENCODEURL(Q4),"Enviar Bienvenida")) | S4: =IF(B4="","","Hola, "&B4&", muy buen día."&CHAR(10)&"Espero que esté teniendo una excelente semana. Le escribo para saber si tiene alguna duda sobre la oferta del *"&D4&"* que revisamos, con gusto le apoyo con información técnica o con las opciones de financiamiento disponibles."&CHAR(10)&"Quedo atento a sus comentarios para seguir avanzando hacia la entrega de su próximo Toyota. Gracias por su tiempo y confianza."&CHAR(10)&CHAR(10)&Config!$B$1) | T4: =IF(S4="","",HYPERLINK("https://wa.me/52"&C4&"?text="&_xlfn.ENCODEURL(S4),"Enviar Seguimiento")) | U4: =IF(B4="","",_xlfn.SWITCH(M4,"Apartado","Hola, "&B4&", buen día. Le confirmo que su apartado por el *"&D4&"* quedó registrado correctamente. Seguimos con el proceso y le mantendré informado(a) de cada paso.","Toma de vehículo","Hola, "&B4&", le comparto que estamos en el proceso de toma de su vehículo actual. En cuanto tengamos el resultado le aviso para continuar con el siguiente paso.","Pago vehículo a cuenta","Hola, "&B4&", quedamos en proceso de pago del vehículo que se toma a cuenta. Cualquier documento o aclaración que se requiera se lo haré saber por este medio.","Firma de contrato","Hola, "&B4&", ya estamos listos para agendar la firma de su contrato. ¿Qué día y hora se le facilita para realizarla?","Facturación","Hola, "&B4&", su unidad ya está en proceso de facturación. En breve le comparto los datos para su confirmación.","Programación de entrega","Hola, "&B4&", con gusto le comparto que ya podemos programar la entrega de su *"&D4&"*. ¿Qué día y hora le acomodan mejor?","Entregado","Hola, "&B4&", ¡muchas felicidades por estrenar su *"&D4&"*! Fue un gusto acompañarle en este proceso. Quedo pendiente de cualquier duda y con gusto le agendo su próxima cita de servicio cuando lo necesite.","Hola, "&B4&", seguimos en contacto para avanzar con el proceso de su próximo Toyota.")&CHAR(10)&CHAR(10)&Config!$B$1) | V4: =IF(U4="","",HYPERLINK("https://wa.me/52"&C4&"?text="&_xlfn.ENCODEURL(U4),"Enviar aviso de etapa")) | W4: =IF(OR(B4="",O4=""),"","Hola, "&B4&", ¡feliz cumpleaños! Le deseo un excelente día rodeado de quienes más quiere. Ha sido un placer acompañarle desde que estrenó su Toyota. ¡Un abrazo!"&CHAR(10)&CHAR(10)&Config!$B$1) | X4: =IF(W4="","",HYPERLINK("https://wa.me/52"&C4&"?text="&_xlfn.ENCODEURL(W4),"Enviar felicitación")) | Y4: =IF(OR(B4="",P4=""),"","Hola, "&B4&", hoy se cumple un año más desde que estrenó su *"&D4&"*. Espero que haya sido un gran compañero de camino. Cualquier cosa que necesite, aquí estoy para apoyarle."&CHAR(10)&CHAR(10)&Config!$B$1) | Z4: =IF(Y4="","",HYPERLINK("https://wa.me/52"&C4&"?text="&_xlfn.ENCODEURL(Y4),"Enviar aniversario")) | AB4: =IF(OR(B4="",AA4=""),"",HYPERLINK("https://wa.me/52"&C4&"?text="&_xlfn.ENCODEURL(_xlfn.SWITCH(AA4,"Bienvenida (primera visita)",Q4,"Seguimiento",S4,"Aviso de Etapa",U4,"Requisitos",AC4,"Datos de Facturación",AD4,"Cumpleaños",W4,"Aniversario",Y4,"")),"Enviar mensaje seleccionado")) | AC4: =IF(B4="","",_xlfn.SWITCH(F4&"|"&G4,"Crédito|Persona física","Hola, "&B4&", para continuar con el proceso de tu *"&D4&"* por "&F4&", estos son los documentos que necesitamos:"&CHAR(10)&CHAR(10)&"- INE"&CHAR(10)&"- Comprobante de domicilio (luz), a nombre del titular"&CHAR(10)&"- Estados de cuenta de los últimos 3 meses"&CHAR(10)&"- Constancia de situación fiscal (no mayor a 3 meses)","Crédito|Persona física con actividad empresarial","Hola, "&B4&", para continuar con el proceso de tu *"&D4&"* por "&F4&", estos son los documentos que necesitamos:"&CHAR(10)&CHAR(10)&"- INE"&CHAR(10)&"- Comprobante de domicilio (luz), a nombre del titular"&CHAR(10)&"- Estados de cuenta de los últimos 3 meses"&CHAR(10)&"- Constancia de situación fiscal (no mayor a 3 meses)"&CHAR(10)&"- Última declaración anual con acuse de recibo","Crédito|Persona moral","Hola, "&B4&", para continuar con el proceso de tu *"&D4&"* por "&F4&", estos son los documentos que necesitamos:"&CHAR(10)&CHAR(10)&"- Identificación oficial vigente del representante legal (INE o pasaporte)"&CHAR(10)&"- Comprobante de domicilio fiscal de la empresa (CFE, no mayor a 3 meses)"&CHAR(10)&"- Comprobante de domicilio del representante legal (CFE, no mayor a 3 meses)"&CHAR(10)&"- Últimos 3 meses de estados de cuenta bancarios de la empresa"&CHAR(10)&"- Constancia de situación fiscal de la empresa (no mayor a 3 meses)"&CHAR(10)&"- Constancia de situación fiscal del representante legal (no mayor a 3 meses)"&CHAR(10)&"- Declaración anual del último ejercicio, en digital, con acuse de recibo"&CHAR(10)&"- Estados financieros de la empresa (Resultados y Balance General), no mayor a 3 meses"&CHAR(10)&"- Escritura constitutiva, poderes o reformas de estatutos (primer acta, poder del representante y última acta)","Contado|Persona física","Hola, "&B4&", para continuar con el proceso de tu *"&D4&"* por "&F4&", estos son los documentos que necesitamos:"&CHAR(10)&CHAR(10)&"- INE"&CHAR(10)&"- Comprobante de domicilio"&CHAR(10)&"- Constancia de situación fiscal (no mayor a 3 meses)","Contado|Persona física con actividad empresarial","Hola, "&B4&", para continuar con el proceso de tu *"&D4&"* por "&F4&", estos son los documentos que necesitamos:"&CHAR(10)&CHAR(10)&"- INE"&CHAR(10)&"- Comprobante de domicilio"&CHAR(10)&"- Constancia de situación fiscal (no mayor a 3 meses)","Contado|Persona moral","Hola, "&B4&", para continuar con el proceso de tu *"&D4&"* por "&F4&", estos son los documentos que necesitamos:"&CHAR(10)&CHAR(10)&"- Identificación oficial vigente del representante legal y accionistas"&CHAR(10)&"- Comprobante de domicilio fiscal de la empresa (no mayor a 3 meses)"&CHAR(10)&"- Comprobante de domicilio del representante legal y accionistas (no mayor a 3 meses)"&CHAR(10)&"- Constancia de situación fiscal de la empresa (no mayor a 3 meses)"&CHAR(10)&"- Constancia de situación fiscal del representante legal y accionistas (no mayor a 3 meses)"&CHAR(10)&"- Escritura constitutiva, poderes o reformas de estatutos (primer acta, poder del representante y última acta)","Selecciona Método de Compra y Tipo de Persona.")&CHAR(10)&CHAR(10)&Config!$B$1) | AD4: =IFERROR(INDEX(Facturación!$Q:$Q,MATCH(B4,Facturación!$A:$A,0)),"")
A5: =IF(B5="","",ROW()-1) | B5: Alejandra Arzate | C5: 4423050736 | D5: Hilux | E5: Base | F5: Crédito | G5: Persona física | H5: No | K5: Son de Jalpan, no tenian tiempo y se les envio cotizacion | L5: Sí | M5: Prospecto / Visita | N5: 46250 | Q5: =IF(OR(B5="",L5<>"Sí"),"","Hola, "&B5&", excelente día. Le saluda *Alejandro Estrada* de Toyota Corregidora."&CHAR(10)&"Muchas gracias por visitarnos y conocer la *"&D5&"*. Fue un placer atenderle. Me pongo a sus órdenes por este medio para resolver cualquier duda que haya surgido o para agendarle una prueba de manejo."&CHAR(10)&"Quedo muy pendiente de lo que necesite para ayudarle a estrenar su próximo Toyota. ¡Saludos!"&CHAR(10)&CHAR(10)&Config!$B$1) | R5: =IF(Q5="","",HYPERLINK("https://wa.me/52"&C5&"?text="&_xlfn.ENCODEURL(Q5),"Enviar Bienvenida")) | S5: =IF(B5="","","Hola, "&B5&", muy buen día."&CHAR(10)&"Espero que esté teniendo una excelente semana. Le escribo para saber si tiene alguna duda sobre la oferta del *"&D5&"* que revisamos, con gusto le apoyo con información técnica o con las opciones de financiamiento disponibles."&CHAR(10)&"Quedo atento a sus comentarios para seguir avanzando hacia la entrega de su próximo Toyota. Gracias por su tiempo y confianza."&CHAR(10)&CHAR(10)&Config!$B$1) | T5: =IF(S5="","",HYPERLINK("https://wa.me/52"&C5&"?text="&_xlfn.ENCODEURL(S5),"Enviar Seguimiento")) | U5: =IF(B5="","",_xlfn.SWITCH(M5,"Apartado","Hola, "&B5&", buen día. Le confirmo que su apartado por el *"&D5&"* quedó registrado correctamente. Seguimos con el proceso y le mantendré informado(a) de cada paso.","Toma de vehículo","Hola, "&B5&", le comparto que estamos en el proceso de toma de su vehículo actual. En cuanto tengamos el resultado le aviso para continuar con el siguiente paso.","Pago vehículo a cuenta","Hola, "&B5&", quedamos en proceso de pago del vehículo que se toma a cuenta. Cualquier documento o aclaración que se requiera se lo haré saber por este medio.","Firma de contrato","Hola, "&B5&", ya estamos listos para agendar la firma de su contrato. ¿Qué día y hora se le facilita para realizarla?","Facturación","Hola, "&B5&", su unidad ya está en proceso de facturación. En breve le comparto los datos para su confirmación.","Programación de entrega","Hola, "&B5&", con gusto le comparto que ya podemos programar la entrega de su *"&D5&"*. ¿Qué día y hora le acomodan mejor?","Entregado","Hola, "&B5&", ¡muchas felicidades por estrenar su *"&D5&"*! Fue un gusto acompañarle en este proceso. Quedo pendiente de cualquier duda y con gusto le agendo su próxima cita de servicio cuando lo necesite.","Hola, "&B5&", seguimos en contacto para avanzar con el proceso de su próximo Toyota.")&CHAR(10)&CHAR(10)&Config!$B$1) | V5: =IF(U5="","",HYPERLINK("https://wa.me/52"&C5&"?text="&_xlfn.ENCODEURL(U5),"Enviar aviso de etapa")) | W5: =IF(OR(B5="",O5=""),"","Hola, "&B5&", ¡feliz cumpleaños! Le deseo un excelente día rodeado de quienes más quiere. Ha sido un placer acompañarle desde que estrenó su Toyota. ¡Un abrazo!"&CHAR(10)&CHAR(10)&Config!$B$1) | X5: =IF(W5="","",HYPERLINK("https://wa.me/52"&C5&"?text="&_xlfn.ENCODEURL(W5),"Enviar felicitación")) | Y5: =IF(OR(B5="",P5=""),"","Hola, "&B5&", hoy se cumple un año más desde que estrenó su *"&D5&"*. Espero que haya sido un gran compañero de camino. Cualquier cosa que necesite, aquí estoy para apoyarle."&CHAR(10)&CHAR(10)&Config!$B$1) | Z5: =IF(Y5="","",HYPERLINK("https://wa.me/52"&C5&"?text="&_xlfn.ENCODEURL(Y5),"Enviar aniversario")) | AB5: =IF(OR(B5="",AA5=""),"",HYPERLINK("https://wa.me/52"&C5&"?text="&_xlfn.ENCODEURL(_xlfn.SWITCH(AA5,"Bienvenida (primera visita)",Q5,"Seguimiento",S5,"Aviso de Etapa",U5,"Requisitos",AC5,"Datos de Facturación",AD5,"Cumpleaños",W5,"Aniversario",Y5,"")),"Enviar mensaje seleccionado")) | AC5: =IF(B5="","",_xlfn.SWITCH(F5&"|"&G5,"Crédito|Persona física","Hola, "&B5&", para continuar con el proceso de tu *"&D5&"* por "&F5&", estos son los documentos que necesitamos:"&CHAR(10)&CHAR(10)&"- INE"&CHAR(10)&"- Comprobante de domicilio (luz), a nombre del titular"&CHAR(10)&"- Estados de cuenta de los últimos 3 meses"&CHAR(10)&"- Constancia de situación fiscal (no mayor a 3 meses)","Crédito|Persona física con actividad empresarial","Hola, "&B5&", para continuar con el proceso de tu *"&D5&"* por "&F5&", estos son los documentos que necesitamos:"&CHAR(10)&CHAR(10)&"- INE"&CHAR(10)&"- Comprobante de domicilio (luz), a nombre del titular"&CHAR(10)&"- Estados de cuenta de los últimos 3 meses"&CHAR(10)&"- Constancia de situación fiscal (no mayor a 3 meses)"&CHAR(10)&"- Última declaración anual con acuse de recibo","Crédito|Persona moral","Hola, "&B5&", para continuar con el proceso de tu *"&D5&"* por "&F5&", estos son los documentos que necesitamos:"&CHAR(10)&CHAR(10)&"- Identificación oficial vigente del representante legal (INE o pasaporte)"&CHAR(10)&"- Comprobante de domicilio fiscal de la empresa (CFE, no mayor a 3 meses)"&CHAR(10)&"- Comprobante de domicilio del representante legal (CFE, no mayor a 3 meses)"&CHAR(10)&"- Últimos 3 meses de estados de cuenta bancarios de la empresa"&CHAR(10)&"- Constancia de situación fiscal de la empresa (no mayor a 3 meses)"&CHAR(10)&"- Constancia de situación fiscal del representante legal (no mayor a 3 meses)"&CHAR(10)&"- Declaración anual del último ejercicio, en digital, con acuse de recibo"&CHAR(10)&"- Estados financieros de la empresa (Resultados y Balance General), no mayor a 3 meses"&CHAR(10)&"- Escritura constitutiva, poderes o reformas de estatutos (primer acta, poder del representante y última acta)","Contado|Persona física","Hola, "&B5&", para continuar con el proceso de tu *"&D5&"* por "&F5&", estos son los documentos que necesitamos:"&CHAR(10)&CHAR(10)&"- INE"&CHAR(10)&"- Comprobante de domicilio"&CHAR(10)&"- Constancia de situación fiscal (no mayor a 3 meses)","Contado|Persona física con actividad empresarial","Hola, "&B5&", para continuar con el proceso de tu *"&D5&"* por "&F5&", estos son los documentos que necesitamos:"&CHAR(10)&CHAR(10)&"- INE"&CHAR(10)&"- Comprobante de domicilio"&CHAR(10)&"- Constancia de situación fiscal (no mayor a 3 meses)","Contado|Persona moral","Hola, "&B5&", para continuar con el proceso de tu *"&D5&"* por "&F5&", estos son los documentos que necesitamos:"&CHAR(10)&CHAR(10)&"- Identificación oficial vigente del representante legal y accionistas"&CHAR(10)&"- Comprobante de domicilio fiscal de la empresa (no mayor a 3 meses)"&CHAR(10)&"- Comprobante de domicilio del representante legal y accionistas (no mayor a 3 meses)"&CHAR(10)&"- Constancia de situación fiscal de la empresa (no mayor a 3 meses)"&CHAR(10)&"- Constancia de situación fiscal del representante legal y accionistas (no mayor a 3 meses)"&CHAR(10)&"- Escritura constitutiva, poderes o reformas de estatutos (primer acta, poder del representante y última acta)","Selecciona Método de Compra y Tipo de Persona.")&CHAR(10)&CHAR(10)&Config!$B$1) | AD5: =IFERROR(INDEX(Facturación!$Q:$Q,MATCH(B5,Facturación!$A:$A,0)),"")
A6: =IF(B6="","",ROW()-1) | B6: Arelis Aguilar | C6: 4425994079 | D6: Sienna | E6: XSE | F6: Crédito | G6: Persona física | H6: No | K6: Está validando si sienna o corolla cross | L6: Sí | M6: Prospecto / Visita | N6: 46250 | Q6: =IF(OR(B6="",L6<>"Sí"),"","Hola, "&B6&", excelente día. Le saluda *Alejandro Estrada* de Toyota Corregidora."&CHAR(10)&"Muchas gracias por visitarnos y conocer la *"&D6&"*. Fue un placer atenderle. Me pongo a sus órdenes por este medio para resolver cualquier duda que haya surgido o para agendarle una prueba de manejo."&CHAR(10)&"Quedo muy pendiente de lo que necesite para ayudarle a estrenar su próximo Toyota. ¡Saludos!"&CHAR(10)&CHAR(10)&Config!$B$1) | R6: =IF(Q6="","",HYPERLINK("https://wa.me/52"&C6&"?text="&_xlfn.ENCODEURL(Q6),"Enviar Bienvenida")) | S6: =IF(B6="","","Hola, "&B6&", muy buen día."&CHAR(10)&"Espero que esté teniendo una excelente semana. Le escribo para saber si tiene alguna duda sobre la oferta del *"&D6&"* que revisamos, con gusto le apoyo con información técnica o con las opciones de financiamiento disponibles."&CHAR(10)&"Quedo atento a sus comentarios para seguir avanzando hacia la entrega de su próximo Toyota. Gracias por su tiempo y confianza."&CHAR(10)&CHAR(10)&Config!$B$1) | T6: =IF(S6="","",HYPERLINK("https://wa.me/52"&C6&"?text="&_xlfn.ENCODEURL(S6),"Enviar Seguimiento")) | U6: =IF(B6="","",_xlfn.SWITCH(M6,"Apartado","Hola, "&B6&", buen día. Le confirmo que su apartado por el *"&D6&"* quedó registrado correctamente. Seguimos con el proceso y le mantendré informado(a) de cada paso.","Toma de vehículo","Hola, "&B6&", le comparto que estamos en el proceso de toma de su vehículo actual. En cuanto tengamos el resultado le aviso para continuar con el siguiente paso.","Pago vehículo a cuenta","Hola, "&B6&", quedamos en proceso de pago del vehículo que se toma a cuenta. Cualquier documento o aclaración que se requiera se lo haré saber por este medio.","Firma de contrato","Hola, "&B6&", ya estamos listos para agendar la firma de su contrato. ¿Qué día y hora se le facilita para realizarla?","Facturación","Hola, "&B6&", su unidad ya está en proceso de facturación. En breve le comparto los datos para su confirmación.","Programación de entrega","Hola, "&B6&", con gusto le comparto que ya podemos programar la entrega de su *"&D6&"*. ¿Qué día y hora le acomodan mejor?","Entregado","Hola, "&B6&", ¡muchas felicidades por estrenar su *"&D6&"*! Fue un gusto acompañarle en este proceso. Quedo pendiente de cualquier duda y con gusto le agendo su próxima cita de servicio cuando lo necesite.","Hola, "&B6&", seguimos en contacto para avanzar con el proceso de su próximo Toyota.")&CHAR(10)&CHAR(10)&Config!$B$1) | V6: =IF(U6="","",HYPERLINK("https://wa.me/52"&C6&"?text="&_xlfn.ENCODEURL(U6),"Enviar aviso de etapa")) | W6: =IF(OR(B6="",O6=""),"","Hola, "&B6&", ¡feliz cumpleaños! Le deseo un excelente día rodeado de quienes más quiere. Ha sido un placer acompañarle desde que estrenó su Toyota. ¡Un abrazo!"&CHAR(10)&CHAR(10)&Config!$B$1) | X6: =IF(W6="","",HYPERLINK("https://wa.me/52"&C6&"?text="&_xlfn.ENCODEURL(W6),"Enviar felicitación")) | Y6: =IF(OR(B6="",P6=""),"","Hola, "&B6&", hoy se cumple un año más desde que estrenó su *"&D6&"*. Espero que haya sido un gran compañero de camino. Cualquier cosa que necesite, aquí estoy para apoyarle."&CHAR(10)&CHAR(10)&Config!$B$1) | Z6: =IF(Y6="","",HYPERLINK("https://wa.me/52"&C6&"?text="&_xlfn.ENCODEURL(Y6),"Enviar aniversario")) | AB6: =IF(OR(B6="",AA6=""),"",HYPERLINK("https://wa.me/52"&C6&"?text="&_xlfn.ENCODEURL(_xlfn.SWITCH(AA6,"Bienvenida (primera visita)",Q6,"Seguimiento",S6,"Aviso de Etapa",U6,"Requisitos",AC6,"Datos de Facturación",AD6,"Cumpleaños",W6,"Aniversario",Y6,"")),"Enviar mensaje seleccionado")) | AC6: =IF(B6="","",_xlfn.SWITCH(F6&"|"&G6,"Crédito|Persona física","Hola, "&B6&", para continuar con el proceso de tu *"&D6&"* por "&F6&", estos son los documentos que necesitamos:"&CHAR(10)&CHAR(10)&"- INE"&CHAR(10)&"- Comprobante de domicilio (luz), a nombre del titular"&CHAR(10)&"- Estados de cuenta de los últimos 3 meses"&CHAR(10)&"- Constancia de situación fiscal (no mayor a 3 meses)","Crédito|Persona física con actividad empresarial","Hola, "&B6&", para continuar con el proceso de tu *"&D6&"* por "&F6&", estos son los documentos que necesitamos:"&CHAR(10)&CHAR(10)&"- INE"&CHAR(10)&"- Comprobante de domicilio (luz), a nombre del titular"&CHAR(10)&"- Estados de cuenta de los últimos 3 meses"&CHAR(10)&"- Constancia de situación fiscal (no mayor a 3 meses)"&CHAR(10)&"- Última declaración anual con acuse de recibo","Crédito|Persona moral","Hola, "&B6&", para continuar con el proceso de tu *"&D6&"* por "&F6&", estos son los documentos que necesitamos:"&CHAR(10)&CHAR(10)&"- Identificación oficial vigente del representante legal (INE o pasaporte)"&CHAR(10)&"- Comprobante de domicilio fiscal de la empresa (CFE, no mayor a 3 meses)"&CHAR(10)&"- Comprobante de domicilio del representante legal (CFE, no mayor a 3 meses)"&CHAR(10)&"- Últimos 3 meses de estados de cuenta bancarios de la empresa"&CHAR(10)&"- Constancia de situación fiscal de la empresa (no mayor a 3 meses)"&CHAR(10)&"- Constancia de situación fiscal del representante legal (no mayor a 3 meses)"&CHAR(10)&"- Declaración anual del último ejercicio, en digital, con acuse de recibo"&CHAR(10)&"- Estados financieros de la empresa (Resultados y Balance General), no mayor a 3 meses"&CHAR(10)&"- Escritura constitutiva, poderes o reformas de estatutos (primer acta, poder del representante y última acta)","Contado|Persona física","Hola, "&B6&", para continuar con el proceso de tu *"&D6&"* por "&F6&", estos son los documentos que necesitamos:"&CHAR(10)&CHAR(10)&"- INE"&CHAR(10)&"- Comprobante de domicilio"&CHAR(10)&"- Constancia de situación fiscal (no mayor a 3 meses)","Contado|Persona física con actividad empresarial","Hola, "&B6&", para continuar con el proceso de tu *"&D6&"* por "&F6&", estos son los documentos que necesitamos:"&CHAR(10)&CHAR(10)&"- INE"&CHAR(10)&"- Comprobante de domicilio"&CHAR(10)&"- Constancia de situación fiscal (no mayor a 3 meses)","Contado|Persona moral","Hola, "&B6&", para continuar con el proceso de tu *"&D6&"* por "&F6&", estos son los documentos que necesitamos:"&CHAR(10)&CHAR(10)&"- Identificación oficial vigente del representante legal y accionistas"&CHAR(10)&"- Comprobante de domicilio fiscal de la empresa (no mayor a 3 meses)"&CHAR(10)&"- Comprobante de domicilio del representante legal y accionistas (no mayor a 3 meses)"&CHAR(10)&"- Constancia de situación fiscal de la empresa (no mayor a 3 meses)"&CHAR(10)&"- Constancia de situación fiscal del representante legal y accionistas (no mayor a 3 meses)"&CHAR(10)&"- Escritura constitutiva, poderes o reformas de estatutos (primer acta, poder del representante y última acta)","Selecciona Método de Compra y Tipo de Persona.")&CHAR(10)&CHAR(10)&Config!$B$1) | AD6: =IFERROR(INDEX(Facturación!$Q:$Q,MATCH(B6,Facturación!$A:$A,0)),"")
A7: =IF(B7="","",ROW()-1) | B7: Jesus Gonzalez | C7: 4421834457 | D7: Hilux | E7: Base | F7: Crédito | G7: Persona física | H7: No | K7: Seguimiento para validar si la compra | L7: Sí | M7: Prospecto / Visita | N7: 46250 | Q7: =IF(OR(B7="",L7<>"Sí"),"","Hola, "&B7&", excelente día. Le saluda *Alejandro Estrada* de Toyota Corregidora."&CHAR(10)&"Muchas gracias por visitarnos y conocer la *"&D7&"*. Fue un placer atenderle. Me pongo a sus órdenes por este medio para resolver cualquier duda que haya surgido o para agendarle una prueba de manejo."&CHAR(10)&"Quedo muy pendiente de lo que necesite para ayudarle a estrenar su próximo Toyota. ¡Saludos!"&CHAR(10)&CHAR(10)&Config!$B$1) | R7: =IF(Q7="","",HYPERLINK("https://wa.me/52"&C7&"?text="&_xlfn.ENCODEURL(Q7),"Enviar Bienvenida")) | S7: =IF(B7="","","Hola, "&B7&", muy buen día."&CHAR(10)&"Espero que esté teniendo una excelente semana. Le escribo para saber si tiene alguna duda sobre la oferta del *"&D7&"* que revisamos, con gusto le apoyo con información técnica o con las opciones de financiamiento disponibles."&CHAR(10)&"Quedo atento a sus comentarios para seguir avanzando hacia la entrega de su próximo Toyota. Gracias por su tiempo y confianza."&CHAR(10)&CHAR(10)&Config!$B$1) | T7: =IF(S7="","",HYPERLINK("https://wa.me/52"&C7&"?text="&_xlfn.ENCODEURL(S7),"Enviar Seguimiento")) | U7: =IF(B7="","",_xlfn.SWITCH(M7,"Apartado","Hola, "&B7&", buen día. Le confirmo que su apartado por el *"&D7&"* quedó registrado correctamente. Seguimos con el proceso y le mantendré informado(a) de cada paso.","Toma de vehículo","Hola, "&B7&", le comparto que estamos en el proceso de toma de su vehículo actual. En cuanto tengamos el resultado le aviso para continuar con el siguiente paso.","Pago vehículo a cuenta","Hola, "&B7&", quedamos en proceso de pago del vehículo que se toma a cuenta. Cualquier documento o aclaración que se requiera se lo haré saber por este medio.","Firma de contrato","Hola, "&B7&", ya estamos listos para agendar la firma de su contrato. ¿Qué día y hora se le facilita para realizarla?","Facturación","Hola, "&B7&", su unidad ya está en proceso de facturación. En breve le comparto los datos para su confirmación.","Programación de entrega","Hola, "&B7&", con gusto le comparto que ya podemos programar la entrega de su *"&D7&"*. ¿Qué día y hora le acomodan mejor?","Entregado","Hola, "&B7&", ¡muchas felicidades por estrenar su *"&D7&"*! Fue un gusto acompañarle en este proceso. Quedo pendiente de cualquier duda y con gusto le agendo su próxima cita de servicio cuando lo necesite.","Hola, "&B7&", seguimos en contacto para avanzar con el proceso de su próximo Toyota.")&CHAR(10)&CHAR(10)&Config!$B$1) | V7: =IF(U7="","",HYPERLINK("https://wa.me/52"&C7&"?text="&_xlfn.ENCODEURL(U7),"Enviar aviso de etapa")) | W7: =IF(OR(B7="",O7=""),"","Hola, "&B7&", ¡feliz cumpleaños! Le deseo un excelente día rodeado de quienes más quiere. Ha sido un placer acompañarle desde que estrenó su Toyota. ¡Un abrazo!"&CHAR(10)&CHAR(10)&Config!$B$1) | X7: =IF(W7="","",HYPERLINK("https://wa.me/52"&C7&"?text="&_xlfn.ENCODEURL(W7),"Enviar felicitación")) | Y7: =IF(OR(B7="",P7=""),"","Hola, "&B7&", hoy se cumple un año más desde que estrenó su *"&D7&"*. Espero que haya sido un gran compañero de camino. Cualquier cosa que necesite, aquí estoy para apoyarle."&CHAR(10)&CHAR(10)&Config!$B$1) | Z7: =IF(Y7="","",HYPERLINK("https://wa.me/52"&C7&"?text="&_xlfn.ENCODEURL(Y7),"Enviar aniversario")) | AB7: =IF(OR(B7="",AA7=""),"",HYPERLINK("https://wa.me/52"&C7&"?text="&_xlfn.ENCODEURL(_xlfn.SWITCH(AA7,"Bienvenida (primera visita)",Q7,"Seguimiento",S7,"Aviso de Etapa",U7,"Requisitos",AC7,"Datos de Facturación",AD7,"Cumpleaños",W7,"Aniversario",Y7,"")),"Enviar mensaje seleccionado")) | AC7: =IF(B7="","",_xlfn.SWITCH(F7&"|"&G7,"Crédito|Persona física","Hola, "&B7&", para continuar con el proceso de tu *"&D7&"* por "&F7&", estos son los documentos que necesitamos:"&CHAR(10)&CHAR(10)&"- INE"&CHAR(10)&"- Comprobante de domicilio (luz), a nombre del titular"&CHAR(10)&"- Estados de cuenta de los últimos 3 meses"&CHAR(10)&"- Constancia de situación fiscal (no mayor a 3 meses)","Crédito|Persona física con actividad empresarial","Hola, "&B7&", para continuar con el proceso de tu *"&D7&"* por "&F7&", estos son los documentos que necesitamos:"&CHAR(10)&CHAR(10)&"- INE"&CHAR(10)&"- Comprobante de domicilio (luz), a nombre del titular"&CHAR(10)&"- Estados de cuenta de los últimos 3 meses"&CHAR(10)&"- Constancia de situación fiscal (no mayor a 3 meses)"&CHAR(10)&"- Última declaración anual con acuse de recibo","Crédito|Persona moral","Hola, "&B7&", para continuar con el proceso de tu *"&D7&"* por "&F7&", estos son los documentos que necesitamos:"&CHAR(10)&CHAR(10)&"- Identificación oficial vigente del representante legal (INE o pasaporte)"&CHAR(10)&"- Comprobante de domicilio fiscal de la empresa (CFE, no mayor a 3 meses)"&CHAR(10)&"- Comprobante de domicilio del representante legal (CFE, no mayor a 3 meses)"&CHAR(10)&"- Últimos 3 meses de estados de cuenta bancarios de la empresa"&CHAR(10)&"- Constancia de situación fiscal de la empresa (no mayor a 3 meses)"&CHAR(10)&"- Constancia de situación fiscal del representante legal (no mayor a 3 meses)"&CHAR(10)&"- Declaración anual del último ejercicio, en digital, con acuse de recibo"&CHAR(10)&"- Estados financieros de la empresa (Resultados y Balance General), no mayor a 3 meses"&CHAR(10)&"- Escritura constitutiva, poderes o reformas de estatutos (primer acta, poder del representante y última acta)","Contado|Persona física","Hola, "&B7&", para continuar con el proceso de tu *"&D7&"* por "&F7&", estos son los documentos que necesitamos:"&CHAR(10)&CHAR(10)&"- INE"&CHAR(10)&"- Comprobante de domicilio"&CHAR(10)&"- Constancia de situación fiscal (no mayor a 3 meses)","Contado|Persona física con actividad empresarial","Hola, "&B7&", para continuar con el proceso de tu *"&D7&"* por "&F7&", estos son los documentos que necesitamos:"&CHAR(10)&CHAR(10)&"- INE"&CHAR(10)&"- Comprobante de domicilio"&CHAR(10)&"- Constancia de situación fiscal (no mayor a 3 meses)","Contado|Persona moral","Hola, "&B7&", para continuar con el proceso de tu *"&D7&"* por "&F7&", estos son los documentos que necesitamos:"&CHAR(10)&CHAR(10)&"- Identificación oficial vigente del representante legal y accionistas"&CHAR(10)&"- Comprobante de domicilio fiscal de la empresa (no mayor a 3 meses)"&CHAR(10)&"- Comprobante de domicilio del representante legal y accionistas (no mayor a 3 meses)"&CHAR(10)&"- Constancia de situación fiscal de la empresa (no mayor a 3 meses)"&CHAR(10)&"- Constancia de situación fiscal del representante legal y accionistas (no mayor a 3 meses)"&CHAR(10)&"- Escritura constitutiva, poderes o reformas de estatutos (primer acta, poder del representante y última acta)","Selecciona Método de Compra y Tipo de Persona.")&CHAR(10)&CHAR(10)&Config!$B$1) | AD7: =IFERROR(INDEX(Facturación!$Q:$Q,MATCH(B7,Facturación!$A:$A,0)),"")
A8: =IF(B8="","",ROW()-1) | B8: José Juan Gonzalez | C8: 4422192465 | D8: Corolla | E8: Base | F8: Crédito | G8: Persona física | H8: No | K8: En seguimiento | L8: Sí | M8: Prospecto / Visita | N8: 46248 | Q8: =IF(OR(B8="",L8<>"Sí"),"","Hola, "&B8&", excelente día. Le saluda *Alejandro Estrada* de Toyota Corregidora."&CHAR(10)&"Muchas gracias por visitarnos y conocer la *"&D8&"*. Fue un placer atenderle. Me pongo a sus órdenes por este medio para resolver cualquier duda que haya surgido o para agendarle una prueba de manejo."&CHAR(10)&"Quedo muy pendiente de lo que necesite para ayudarle a estrenar su próximo Toyota. ¡Saludos!"&CHAR(10)&CHAR(10)&Config!$B$1) | R8: =IF(Q8="","",HYPERLINK("https://wa.me/52"&C8&"?text="&_xlfn.ENCODEURL(Q8),"Enviar Bienvenida")) | S8: =IF(B8="","","Hola, "&B8&", muy buen día."&CHAR(10)&"Espero que esté teniendo una excelente semana. Le escribo para saber si tiene alguna duda sobre la oferta del *"&D8&"* que revisamos, con gusto le apoyo con información técnica o con las opciones de financiamiento disponibles."&CHAR(10)&"Quedo atento a sus comentarios para seguir avanzando hacia la entrega de su próximo Toyota. Gracias por su tiempo y confianza."&CHAR(10)&CHAR(10)&Config!$B$1) | T8: =IF(S8="","",HYPERLINK("https://wa.me/52"&C8&"?text="&_xlfn.ENCODEURL(S8),"Enviar Seguimiento")) | U8: =IF(B8="","",_xlfn.SWITCH(M8,"Apartado","Hola, "&B8&", buen día. Le confirmo que su apartado por el *"&D8&"* quedó registrado correctamente. Seguimos con el proceso y le mantendré informado(a) de cada paso.","Toma de vehículo","Hola, "&B8&", le comparto que estamos en el proceso de toma de su vehículo actual. En cuanto tengamos el resultado le aviso para continuar con el siguiente paso.","Pago vehículo a cuenta","Hola, "&B8&", quedamos en proceso de pago del vehículo que se toma a cuenta. Cualquier documento o aclaración que se requiera se lo haré saber por este medio.","Firma de contrato","Hola, "&B8&", ya estamos listos para agendar la firma de su contrato. ¿Qué día y hora se le facilita para realizarla?","Facturación","Hola, "&B8&", su unidad ya está en proceso de facturación. En breve le comparto los datos para su confirmación.","Programación de entrega","Hola, "&B8&", con gusto le comparto que ya podemos programar la entrega de su *"&D8&"*. ¿Qué día y hora le acomodan mejor?","Entregado","Hola, "&B8&", ¡muchas felicidades por estrenar su *"&D8&"*! Fue un gusto acompañarle en este proceso. Quedo pendiente de cualquier duda y con gusto le agendo su próxima cita de servicio cuando lo necesite.","Hola, "&B8&", seguimos en contacto para avanzar con el proceso de su próximo Toyota.")&CHAR(10)&CHAR(10)&Config!$B$1) | V8: =IF(U8="","",HYPERLINK("https://wa.me/52"&C8&"?text="&_xlfn.ENCODEURL(U8),"Enviar aviso de etapa")) | W8: =IF(OR(B8="",O8=""),"","Hola, "&B8&", ¡feliz cumpleaños! Le deseo un excelente día rodeado de quienes más quiere. Ha sido un placer acompañarle desde que estrenó su Toyota. ¡Un abrazo!"&CHAR(10)&CHAR(10)&Config!$B$1) | X8: =IF(W8="","",HYPERLINK("https://wa.me/52"&C8&"?text="&_xlfn.ENCODEURL(W8),"Enviar felicitación")) | Y8: =IF(OR(B8="",P8=""),"","Hola, "&B8&", hoy se cumple un año más desde que estrenó su *"&D8&"*. Espero que haya sido un gran compañero de camino. Cualquier cosa que necesite, aquí estoy para apoyarle."&CHAR(10)&CHAR(10)&Config!$B$1) | Z8: =IF(Y8="","",HYPERLINK("https://wa.me/52"&C8&"?text="&_xlfn.ENCODEURL(Y8),"Enviar aniversario")) | AB8: =IF(OR(B8="",AA8=""),"",HYPERLINK("https://wa.me/52"&C8&"?text="&_xlfn.ENCODEURL(_xlfn.SWITCH(AA8,"Bienvenida (primera visita)",Q8,"Seguimiento",S8,"Aviso de Etapa",U8,"Requisitos",AC8,"Datos de Facturación",AD8,"Cumpleaños",W8,"Aniversario",Y8,"")),"Enviar mensaje seleccionado")) | AC8: =IF(B8="","",_xlfn.SWITCH(F8&"|"&G8,"Crédito|Persona física","Hola, "&B8&", para continuar con el proceso de tu *"&D8&"* por "&F8&", estos son los documentos que necesitamos:"&CHAR(10)&CHAR(10)&"- INE"&CHAR(10)&"- Comprobante de domicilio (luz), a nombre del titular"&CHAR(10)&"- Estados de cuenta de los últimos 3 meses"&CHAR(10)&"- Constancia de situación fiscal (no mayor a 3 meses)","Crédito|Persona física con actividad empresarial","Hola, "&B8&", para continuar con el proceso de tu *"&D8&"* por "&F8&", estos son los documentos que necesitamos:"&CHAR(10)&CHAR(10)&"- INE"&CHAR(10)&"- Comprobante de domicilio (luz), a nombre del titular"&CHAR(10)&"- Estados de cuenta de los últimos 3 meses"&CHAR(10)&"- Constancia de situación fiscal (no mayor a 3 meses)"&CHAR(10)&"- Última declaración anual con acuse de recibo","Crédito|Persona moral","Hola, "&B8&", para continuar con el proceso de tu *"&D8&"* por "&F8&", estos son los documentos que necesitamos:"&CHAR(10)&CHAR(10)&"- Identificación oficial vigente del representante legal (INE o pasaporte)"&CHAR(10)&"- Comprobante de domicilio fiscal de la empresa (CFE, no mayor a 3 meses)"&CHAR(10)&"- Comprobante de domicilio del representante legal (CFE, no mayor a 3 meses)"&CHAR(10)&"- Últimos 3 meses de estados de cuenta bancarios de la empresa"&CHAR(10)&"- Constancia de situación fiscal de la empresa (no mayor a 3 meses)"&CHAR(10)&"- Constancia de situación fiscal del representante legal (no mayor a 3 meses)"&CHAR(10)&"- Declaración anual del último ejercicio, en digital, con acuse de recibo"&CHAR(10)&"- Estados financieros de la empresa (Resultados y Balance General), no mayor a 3 meses"&CHAR(10)&"- Escritura constitutiva, poderes o reformas de estatutos (primer acta, poder del representante y última acta)","Contado|Persona física","Hola, "&B8&", para continuar con el proceso de tu *"&D8&"* por "&F8&", estos son los documentos que necesitamos:"&CHAR(10)&CHAR(10)&"- INE"&CHAR(10)&"- Comprobante de domicilio"&CHAR(10)&"- Constancia de situación fiscal (no mayor a 3 meses)","Contado|Persona física con actividad empresarial","Hola, "&B8&", para continuar con el proceso de tu *"&D8&"* por "&F8&", estos son los documentos que necesitamos:"&CHAR(10)&CHAR(10)&"- INE"&CHAR(10)&"- Comprobante de domicilio"&CHAR(10)&"- Constancia de situación fiscal (no mayor a 3 meses)","Contado|Persona moral","Hola, "&B8&", para continuar con el proceso de tu *"&D8&"* por "&F8&", estos son los documentos que necesitamos:"&CHAR(10)&CHAR(10)&"- Identificación oficial vigente del representante legal y accionistas"&CHAR(10)&"- Comprobante de domicilio fiscal de la empresa (no mayor a 3 meses)"&CHAR(10)&"- Comprobante de domicilio del representante legal y accionistas (no mayor a 3 meses)"&CHAR(10)&"- Constancia de situación fiscal de la empresa (no mayor a 3 meses)"&CHAR(10)&"- Constancia de situación fiscal del representante legal y accionistas (no mayor a 3 meses)"&CHAR(10)&"- Escritura constitutiva, poderes o reformas de estatutos (primer acta, poder del representante y última acta)","Selecciona Método de Compra y Tipo de Persona.")&CHAR(10)&CHAR(10)&Config!$B$1) | AD8: =IFERROR(INDEX(Facturación!$Q:$Q,MATCH(B8,Facturación!$A:$A,0)),"")
A9: =IF(B9="","",ROW()-1) | B9: Rodrigo Aguilera | C9: 4421916064 | D9: Rav-4 | E9: XLE | F9: Crédito | G9: Persona física | H9: No | K9: No le gusto el tiempo de espera | L9: Sí | M9: Prospecto / Visita | N9: 46248 | Q9: =IF(OR(B9="",L9<>"Sí"),"","Hola, "&B9&", excelente día. Le saluda *Alejandro Estrada* de Toyota Corregidora."&CHAR(10)&"Muchas gracias por visitarnos y conocer la *"&D9&"*. Fue un placer atenderle. Me pongo a sus órdenes por este medio para resolver cualquier duda que haya surgido o para agendarle una prueba de manejo."&CHAR(10)&"Quedo muy pendiente de lo que necesite para ayudarle a estrenar su próximo Toyota. ¡Saludos!"&CHAR(10)&CHAR(10)&Config!$B$1) | R9: =IF(Q9="","",HYPERLINK("https://wa.me/52"&C9&"?text="&_xlfn.ENCODEURL(Q9),"Enviar Bienvenida")) | S9: =IF(B9="","","Hola, "&B9&", muy buen día."&CHAR(10)&"Espero que esté teniendo una excelente semana. Le escribo para saber si tiene alguna duda sobre la oferta del *"&D9&"* que revisamos, con gusto le apoyo con información técnica o con las opciones de financiamiento disponibles."&CHAR(10)&"Quedo atento a sus comentarios para seguir avanzando hacia la entrega de su próximo Toyota. Gracias por su tiempo y confianza."&CHAR(10)&CHAR(10)&Config!$B$1) | T9: =IF(S9="","",HYPERLINK("https://wa.me/52"&C9&"?text="&_xlfn.ENCODEURL(S9),"Enviar Seguimiento")) | U9: =IF(B9="","",_xlfn.SWITCH(M9,"Apartado","Hola, "&B9&", buen día. Le confirmo que su apartado por el *"&D9&"* quedó registrado correctamente. Seguimos con el proceso y le mantendré informado(a) de cada paso.","Toma de vehículo","Hola, "&B9&", le comparto que estamos en el proceso de toma de su vehículo actual. En cuanto tengamos el resultado le aviso para continuar con el siguiente paso.","Pago vehículo a cuenta","Hola, "&B9&", quedamos en proceso de pago del vehículo que se toma a cuenta. Cualquier documento o aclaración que se requiera se lo haré saber por este medio.","Firma de contrato","Hola, "&B9&", ya estamos listos para agendar la firma de su contrato. ¿Qué día y hora se le facilita para realizarla?","Facturación","Hola, "&B9&", su unidad ya está en proceso de facturación. En breve le comparto los datos para su confirmación.","Programación de entrega","Hola, "&B9&", con gusto le comparto que ya podemos programar la entrega de su *"&D9&"*. ¿Qué día y hora le acomodan mejor?","Entregado","Hola, "&B9&", ¡muchas felicidades por estrenar su *"&D9&"*! Fue un gusto acompañarle en este proceso. Quedo pendiente de cualquier duda y con gusto le agendo su próxima cita de servicio cuando lo necesite.","Hola, "&B9&", seguimos en contacto para avanzar con el proceso de su próximo Toyota.")&CHAR(10)&CHAR(10)&Config!$B$1) | V9: =IF(U9="","",HYPERLINK("https://wa.me/52"&C9&"?text="&_xlfn.ENCODEURL(U9),"Enviar aviso de etapa")) | W9: =IF(OR(B9="",O9=""),"","Hola, "&B9&", ¡feliz cumpleaños! Le deseo un excelente día rodeado de quienes más quiere. Ha sido un placer acompañarle desde que estrenó su Toyota. ¡Un abrazo!"&CHAR(10)&CHAR(10)&Config!$B$1) | X9: =IF(W9="","",HYPERLINK("https://wa.me/52"&C9&"?text="&_xlfn.ENCODEURL(W9),"Enviar felicitación")) | Y9: =IF(OR(B9="",P9=""),"","Hola, "&B9&", hoy se cumple un año más desde que estrenó su *"&D9&"*. Espero que haya sido un gran compañero de camino. Cualquier cosa que necesite, aquí estoy para apoyarle."&CHAR(10)&CHAR(10)&Config!$B$1) | Z9: =IF(Y9="","",HYPERLINK("https://wa.me/52"&C9&"?text="&_xlfn.ENCODEURL(Y9),"Enviar aniversario")) | AB9: =IF(OR(B9="",AA9=""),"",HYPERLINK("https://wa.me/52"&C9&"?text="&_xlfn.ENCODEURL(_xlfn.SWITCH(AA9,"Bienvenida (primera visita)",Q9,"Seguimiento",S9,"Aviso de Etapa",U9,"Requisitos",AC9,"Datos de Facturación",AD9,"Cumpleaños",W9,"Aniversario",Y9,"")),"Enviar mensaje seleccionado")) | AC9: =IF(B9="","",_xlfn.SWITCH(F9&"|"&G9,"Crédito|Persona física","Hola, "&B9&", para continuar con el proceso de tu *"&D9&"* por "&F9&", estos son los documentos que necesitamos:"&CHAR(10)&CHAR(10)&"- INE"&CHAR(10)&"- Comprobante de domicilio (luz), a nombre del titular"&CHAR(10)&"- Estados de cuenta de los últimos 3 meses"&CHAR(10)&"- Constancia de situación fiscal (no mayor a 3 meses)","Crédito|Persona física con actividad empresarial","Hola, "&B9&", para continuar con el proceso de tu *"&D9&"* por "&F9&", estos son los documentos que necesitamos:"&CHAR(10)&CHAR(10)&"- INE"&CHAR(10)&"- Comprobante de domicilio (luz), a nombre del titular"&CHAR(10)&"- Estados de cuenta de los últimos 3 meses"&CHAR(10)&"- Constancia de situación fiscal (no mayor a 3 meses)"&CHAR(10)&"- Última declaración anual con acuse de recibo","Crédito|Persona moral","Hola, "&B9&", para continuar con el proceso de tu *"&D9&"* por "&F9&", estos son los documentos que necesitamos:"&CHAR(10)&CHAR(10)&"- Identificación oficial vigente del representante legal (INE o pasaporte)"&CHAR(10)&"- Comprobante de domicilio fiscal de la empresa (CFE, no mayor a 3 meses)"&CHAR(10)&"- Comprobante de domicilio del representante legal (CFE, no mayor a 3 meses)"&CHAR(10)&"- Últimos 3 meses de estados de cuenta bancarios de la empresa"&CHAR(10)&"- Constancia de situación fiscal de la empresa (no mayor a 3 meses)"&CHAR(10)&"- Constancia de situación fiscal del representante legal (no mayor a 3 meses)"&CHAR(10)&"- Declaración anual del último ejercicio, en digital, con acuse de recibo"&CHAR(10)&"- Estados financieros de la empresa (Resultados y Balance General), no mayor a 3 meses"&CHAR(10)&"- Escritura constitutiva, poderes o reformas de estatutos (primer acta, poder del representante y última acta)","Contado|Persona física","Hola, "&B9&", para continuar con el proceso de tu *"&D9&"* por "&F9&", estos son los documentos que necesitamos:"&CHAR(10)&CHAR(10)&"- INE"&CHAR(10)&"- Comprobante de domicilio"&CHAR(10)&"- Constancia de situación fiscal (no mayor a 3 meses)","Contado|Persona física con actividad empresarial","Hola, "&B9&", para continuar con el proceso de tu *"&D9&"* por "&F9&", estos son los documentos que necesitamos:"&CHAR(10)&CHAR(10)&"- INE"&CHAR(10)&"- Comprobante de domicilio"&CHAR(10)&"- Constancia de situación fiscal (no mayor a 3 meses)","Contado|Persona moral","Hola, "&B9&", para continuar con el proceso de tu *"&D9&"* por "&F9&", estos son los documentos que necesitamos:"&CHAR(10)&CHAR(10)&"- Identificación oficial vigente del representante legal y accionistas"&CHAR(10)&"- Comprobante de domicilio fiscal de la empresa (no mayor a 3 meses)"&CHAR(10)&"- Comprobante de domicilio del representante legal y accionistas (no mayor a 3 meses)"&CHAR(10)&"- Constancia de situación fiscal de la empresa (no mayor a 3 meses)"&CHAR(10)&"- Constancia de situación fiscal del representante legal y accionistas (no mayor a 3 meses)"&CHAR(10)&"- Escritura constitutiva, poderes o reformas de estatutos (primer acta, poder del representante y última acta)","Selecciona Método de Compra y Tipo de Persona.")&CHAR(10)&CHAR(10)&Config!$B$1) | AD9: =IFERROR(INDEX(Facturación!$Q:$Q,MATCH(B9,Facturación!$A:$A,0)),"")
